Workbook

Sheet Summary
AB2: Deep Conditioner
B4: Product Matrix
B6: Product Classification | H6: Product Assessment | N6: Ingredient Sensitivity Flags | S6: Standards | X6: Usage & Recommendations
B7: SKU | C7: Brand | D7: Product Name | E7: Product Category | F7: Price | G7: Size | H7: Primary Focus | I7: Hold | J7: Porosity Suitability | K7: Density Suitability | L7: Climate Performance | M7: Build Up Risk | N7: Aloe | O7: Coconut | P7: Protein | Q7: Humectant heavy | R7: Butter/Oil Heavy | S7: CG Approved | T7: Silicone Free | U7: Sulfate Free | V7: Beginner Friendly | W7: Advanced User Product | X7: Best Used When | Y7: Not Ideal If | Z7: Hero Use Case | AA7: Pairs well with | AB7: Product Alternatives | AC7: Best Seller
B8: AIM-CLIC-237 | C8: As I Am | D8: =VLOOKUP(B8,'Shopify Catalog'!$A:$C,3,FALSE) -> As I Am Classic Leave In Conditioner | E8: Leave In | F8: =VLOOKUP(Summary!B8,'Shopify Catalog'!A:X,24,FALSE) -> 70 | H8: Moisture | I8: None | J8: All | K8: All | L8: Heat + Humidity | M8: No | N8: No | O8: No | P8: No | Q8: No | R8: No | S8: Yes | T8: Yes | U8: Yes | V8: Yes | W8: No | X8: Damp | AA8: Stylers | AB8: Treluxe Untie the Knot | AC8: No
B9: AIM-JBOHM-237 | C9: As I Am | D9: AS I AM Jamaican Black Castor Oil Hair Mask | E9: Deep Conditioner | F9: =VLOOKUP(Summary!B9,'Shopify Catalog'!A:X,24,FALSE) -> 75 | H9: Moisture | I9: None | J9: All | K9: All | L9: Heat + Humidity | M9: No | N9: No | O9: No | P9: No | Q9: No | R9: No | S9: Yes | T9: Yes | U9: Yes | V9: Yes | X9: Wet | AA9: Treatments | AB9: Camille Rose Algae Renew Deep Conditioning Mask | AC9: No
B10: AIM-DOLIC-237 | C10: As I Am | D10: =VLOOKUP(B10,'Shopify Catalog'!$A:$C,3,FALSE) -> As I Am Dry & Itchy Scalp Olive & Tea Tree Oil Leave in Conditioner | E10: Leave In | F10: =VLOOKUP(Summary!B10,'Shopify Catalog'!A:X,24,FALSE) -> 70 | H10: Scalp | I10: None | J10: All | K10: All | L10: Heat + Humidity | M10: No | N10: Yes | O10: Yes | P10: No | Q10: Yes | R10: Yes | S10: Yes | T10: Yes | U10: Yes | V10: No | X10: Wet | AA10: Stylers | AB10: Breahni Weightless Detangler | AC10: No
B11: AIM-DIOT-118 | C11: As I Am | D11: =VLOOKUP(B11,'Shopify Catalog'!$A:$C,3,FALSE) -> As I Am Dry & Itchy Scalp Care Olive & Tea Tree Oil Treatment | E11: Treatment | F11: =VLOOKUP(Summary!B11,'Shopify Catalog'!A:X,24,FALSE) -> 65 | H11: Scalp | I11: None | J11: High | K11: All | L11: Heat + Humidity | M11: No | N11: No | O11: Yes | P11: No | Q11: Yes | R11: Yes | S11: Yes | T11: Yes | U11: Yes | V11: No | X11: Dry | AA11: Stylers | AB11: Curls & Potions Chebula & Green Tea Herba lMint Hair & Scalp Oil | AC11: No
B12: AIM-DTCT-355 | C12: As I Am | D12: =VLOOKUP(B12,'Shopify Catalog'!$A:$C,3,FALSE) -> As I Am Dry & Itchy Scalp Care Olive & Tea Tree Conditioner | E12: Instant Conditioner | F12: =VLOOKUP(Summary!B12,'Shopify Catalog'!A:X,24,FALSE) -> 70 | H12: Scalp | I12: None | J12: High | K12: Thick | L12: Heat + Humidity | M12: No | N12: Yes | O12: Yes | P12: No | Q12: Yes | R12: Yes | S12: Yes | T12: Yes | U12: Yes | V12: No | X12: Wet | AA12: Hair Mask | AB12: Inahsi Soothing Mint Moisturizing Conditioner | AC12: No
B13: AIM-DOOS-355 | C13: As I Am | D13: =VLOOKUP(B13,'Shopify Catalog'!$A:$C,3,FALSE) -> As I Am Dry & Itchy Scalp Olive & Tea Tree Oil Shampoo | E13: Cleanser | F13: =VLOOKUP(Summary!B13,'Shopify Catalog'!A:X,24,FALSE) -> 70 | H13: Scalp | I13: None | J13: High | K13: All | L13: Heat + Humidity | M13: No | N13: Yes | O13: No | P13: No | Q13: Yes | R13: No | S13: Yes | T13: Yes | U13: Yes | V13: Yes | X13: Wet | AA13: Conditioners | AB13: Curls & Potions Chebe Scalp Length Retention Shampoo | AC13: No
B14: AIM-JBSP-237 | C14: As I Am | D14: =VLOOKUP(B14,'Shopify Catalog'!$A:$C,3,FALSE) -> As I Am JBCO Shampoo | E14: Cleanser | F14: =VLOOKUP(Summary!B14,'Shopify Catalog'!A:X,24,FALSE) -> 70 | H14: Moisture | I14: None | J14: High | K14: All | L14: Heat + Humidity | M14: No | N14: No | O14: No | P14: No | Q14: No | R14: Yes | S14: Yes | T14: Yes | U14: Yes | V14: Yes | X14: Wet | AA14: Conditioners | AB14: Camille Rose Rose Cleansing Milk | AC14: No
B15: AIM-CCW-473 | C15: As I Am | D15: =VLOOKUP(B15,'Shopify Catalog'!$A:$C,3,FALSE) -> As I Am Coconut CoWash | E15: Cleanser | F15: =VLOOKUP(Summary!B15,'Shopify Catalog'!A:X,24,FALSE) -> 70 | H15: Moisture | I15: None | J15: All | K15: All | L15: Heat + Humidity | M15: No | N15: No | O15: Yes | P15: No | Q15: No | R15: Yes | S15: Yes | T15: Yes | U15: Yes | V15: Yes | X15: Wet | AA15: Cleansers | AC15: No
B16: BRN-CDC-237 | C16: Breahni | D16: =VLOOKUP(B16,'Shopify Catalog'!$A:$C,3,FALSE) -> Breahni Curl Defining Cream | E16: Styler | F16: =VLOOKUP(Summary!B16,'Shopify Catalog'!A:X,24,FALSE) -> 85 | H16: Definition | I16: Soft | J16: High | K16: All | L16: Heat + Humidity | M16: No | N16: No | O16: No | P16: No | Q16: Yes | R16: No | S16: Yes | T16: Yes | U16: Yes | V16: Yes | X16: Damp | AA16: Leave In | AB16: Treluxe Curl Supreme 4-in-1 Hydrating Crème | AC16: No
B17: BRN-CDC-59 | C17: Breahni | D17: Breahni Curl Defining Cream | E17: Styler | F17: =VLOOKUP(Summary!B17,'Shopify Catalog'!A:X,24,FALSE) -> 35 | H17: Definition | I17: Soft | J17: High | K17: All | L17: Heat + Humidity | M17: No | N17: No | O17: No | P17: No | Q17: Yes | R17: No | S17: Yes | T17: Yes | U17: Yes | V17: Yes | X17: Damp | AA17: Leave In | AC17: No
B18: BRN-LSG-237 | C18: Breahni | D18: =VLOOKUP(B18,'Shopify Catalog'!$A:$C,3,FALSE) -> Breahni Light Styling Gel | E18: Styler | F18: =VLOOKUP(Summary!B18,'Shopify Catalog'!A:X,24,FALSE) -> 80 | H18: Definition | I18: Medium | J18: All | K18: Fine | L18: Heat + Humidity | M18: No | N18: No | O18: No | P18: No | Q18: No | R18: Yes | S18: Yes | T18: Yes | U18: Yes | V18: Yes | X18: Damp | AA18: Leave In | AB18: Ecoslay Orange Marmalade CuRL Definer | AC18: No
B19: BRN-LSG-59 | C19: Breahni | D19: Breahni Light Styling Gel | E19: Styler | F19: =VLOOKUP(Summary!B19,'Shopify Catalog'!A:X,24,FALSE) -> 35 | H19: Definition | I19: Medium | J19: All | K19: Fine | L19: Heat + Humidity | M19: No | N19: No | O19: No | P19: No | Q19: No | R19: Yes | S19: Yes | T19: Yes | U19: Yes | V19: Yes | X19: Damp | AA19: Leave In | AB19: Ecoslay Orange Marmalade CuRL Definer | AC19: No
B20: BRN-MOM-237 | C20: Breahni | D20: =VLOOKUP(B20,'Shopify Catalog'!$A:$C,3,FALSE) -> Breahni Moisture Milk | F20: =VLOOKUP(Summary!B20,'Shopify Catalog'!A:X,24,FALSE) -> 70 | H20: Moisture | I20: None | J20: All | K20: Fine | L20: Heat + Humidity | M20: No | N20: No | O20: No | P20: No | Q20: No | R20: Yes | S20: Yes | T20: Yes | U20: Yes | V20: Yes | X20: Damp | AA20: Leave In | AB20: Camille Rose Curl Love Moisture Milk | AC20: No
B21: BRN-MOM-59 | C21: Breahni | D21: Breahni Moisture Milk | F21: =VLOOKUP(Summary!B21,'Shopify Catalog'!A:X,24,FALSE) -> 30 | H21: Moisture | I21: None | J21: All | K21: Fine | L21: Heat + Humidity | M21: No | N21: No | O21: No | P21: No | Q21: No | R21: Yes | S21: Yes | T21: Yes | U21: Yes | V21: Yes | X21: Damp | AA21: Leave In | AB21: Camille Rose Curl Love Moisture Milk
B22: BRN-LIC-237 | C22: Breahni | D22: =VLOOKUP(B22,'Shopify Catalog'!$A:$C,3,FALSE) -> Breahni Leave In Conditioner | E22: Leave In | F22: =VLOOKUP(Summary!B22,'Shopify Catalog'!A:X,24,FALSE) -> 65 | H22: Moisture | I22: None | J22: Low | K22: All | L22: Heat + Humidity | M22: No | N22: Yes | O22: No | P22: No | Q22: Yes | R22: No | S22: Yes | T22: Yes | U22: Yes | V22: Yes | X22: Damp | AA22: Stylers | AB22: Kinky Curly Knot Today Leave In Conditioner | AC22: No
B23: BRN-LIC-59 | C23: Breahni | D23: Breahni Leave In Conditioner | E23: Leave In | F23: =VLOOKUP(Summary!B23,'Shopify Catalog'!A:X,24,FALSE) -> 25 | H23: Moisture | I23: None | J23: Low | K23: All | L23: Heat + Humidity | M23: No | N23: Yes | O23: No | P23: No | Q23: Yes | R23: No | S23: Yes | T23: Yes | U23: Yes | V23: Yes | X23: Damp | AA23: Stylers | AC23: No
B24: BRN-HHR-237 | C24: Breahni | D24: =VLOOKUP(B24,'Shopify Catalog'!$A:$C,3,FALSE) -> Breahni Hydrating Hair Refresher | F24: =VLOOKUP(Summary!B24,'Shopify Catalog'!A:X,24,FALSE) -> 65 | H24: Moisture | I24: Soft | J24: All | K24: All | L24: Heat + Humidity | M24: No | N24: Yes | O24: No | P24: Yes | Q24: Yes | R24: No | S24: Yes | T24: Yes | U24: Yes | V24: Yes | X24: Dry | AA24: Stylers | AB24: Camille Rose Honey Dew Liquid Moisture Refresher | AC24: No
B25: BRN-HHR-59 | C25: Breahni | D25: Breahni Hydrating Hair Refresher | F25: =VLOOKUP(Summary!B25,'Shopify Catalog'!A:X,24,FALSE) -> 25 | H25: Moisture | I25: Soft | J25: All | K25: All | L25: Heat + Humidity | M25: No | N25: Yes | O25: No | P25: Yes | Q25: Yes | R25: No | S25: Yes | T25: Yes | U25: Yes | V25: Yes | X25: Dry | AA25: Stylers | AC25: No
B26: BRN-WED-237 | C26: Breahni | D26: =VLOOKUP(B26,'Shopify Catalog'!$A:$C,3,FALSE) -> Breahni Weightless Detangler | F26: =VLOOKUP(Summary!B26,'Shopify Catalog'!A:X,24,FALSE) -> 65 | H26: Detangler | I26: None | J26: All | K26: Fine | L26: Heat + Humidity | M26: No | N26: Yes | O26: Yes | P26: No | Q26: Yes | R26: No | S26: Yes | T26: Yes | U26: Yes | V26: Yes | X26: Damp | AA26: Stylers | AB26: Kinky Curly Knot Today Leave In Conditioner | AC26: No
B27: BRN-WED-59 | C27: Breahni | D27: Breahni Weightless Detangler | F27: =VLOOKUP(Summary!B27,'Shopify Catalog'!A:X,24,FALSE) -> 25 | H27: Detangler | I27: None | J27: All | K27: Fine | L27: Heat + Humidity | M27: No | N27: Yes | O27: Yes | P27: No | Q27: Yes | R27: No | S27: Yes | T27: Yes | U27: Yes | V27: Yes | X27: Damp | AA27: Stylers | AC27: No
B28: CAB-LPOT-118 | C28: Cachos Brazil | D28: =VLOOKUP(B28,'Shopify Catalog'!$A:$C,3,FALSE) -> Cachos Brazil Low Porosity Hair & Scalp Elixir - Oil Treatment | E28: Oil | F28: =VLOOKUP(Summary!B28,'Shopify Catalog'!A:X,24,FALSE) -> 70 | H28: Sealant | I28: None | J28: Low | K28: All | L28: Heat + Humidity | M28: No | N28: No | O28: No | P28: No | Q28: No | R28: No | S28: Yes | T28: Yes | U28: Yes | V28: No | X28: Dry & Damp | AA28: Stylers | AB28: Innersense I create Shine | AC28: No
B29: CAB-HPTH-118 | C29: Cachos Brazil | D29: =VLOOKUP(B29,'Shopify Catalog'!$A:$C,3,FALSE) -> Cachos Brazil High Porosity Hair & Scalp Elixir - Ideal for Color Treated Hair | F29: =VLOOKUP(Summary!B29,'Shopify Catalog'!A:X,24,FALSE) -> 70 | H29: Scalp Care | I29: None | J29: High | K29: All | L29: Heat + Humidity | M29: No | N29: No | O29: No | P29: No | Q29: No | R29: No | S29: Yes | T29: Yes | U29: Yes | V29: No | X29: Dry & Damp | AA29: Stylers | AB29: Camille Rose Rosemary Mint Strengthening Oil | AC29: No
B30: CAB-LPHB-118 | C30: Cachos Brazil | D30: =VLOOKUP(B30,'Shopify Catalog'!$A:$C,3,FALSE) -> Cachos Brazil Low Porosity Hair Butter | F30: =VLOOKUP(Summary!B30,'Shopify Catalog'!A:X,24,FALSE) -> 75 | H30: Sealant | I30: None | J30: Low | K30: All | L30: Heat + Humidity | M30: No | N30: No | O30: No | P30: No | Q30: No | R30: No | S30: Yes | T30: Yes | U30: Yes | V30: Yes | X30: Dry & Damp | AA30: Stylers | AB30: Camille Rose Almond Jai Twisting Butter | AC30: No
B31: CAB-CWDC-237 | C31: Cachos Brazil | D31: Cachos Brazil Brazilian Combing Crème-Wash & Go Styler & Deep Conditioner | E31: Styler | F31: =VLOOKUP(Summary!B31,'Shopify Catalog'!A:X,24,FALSE) -> 80 | H31: Moisture | I31: Soft | J31: All | K31: All | L31: Heat + Humidity | M31: No | N31: No | O31: No | P31: No | Q31: No | R31: No | S31: Yes | T31: Yes | U31: Yes | V31: Yes | X31: Wet | AA31: Oils & Butters | AB31: Treluxe Curl Suipreme 4-in-1 Hydrating Crème | AC31: No
B32: CAB-CWDC-118 | C32: Cachos Brazil | D32: =VLOOKUP(B32,'Shopify Catalog'!$A:$C,3,FALSE) -> Cachos Brazil Brazilian Combing Crème - Wash & Go Styler & Deep Conditioner | E32: Styler | F32: =VLOOKUP(Summary!B32,'Shopify Catalog'!A:X,24,FALSE) -> 57 | H32: Moisture | I32: Soft | J32: All | K32: All | L32: Heat + Humidity | M32: No | N32: No | O32: No | P32: No | Q32: No | R32: No | S32: Yes | T32: Yes | U32: Yes | V32: Yes | X32: Wet | AA32: Oils & Butters | AB32: Treluxe Curl Suipreme 4-in-1 Hydrating Crème | AC32: No
B33: CAB-LCMR-118 | C33: Cachos Brazil | D33: =VLOOKUP(B33,'Shopify Catalog'!$A:$C,3,FALSE) -> Cachos Brazil Rio Mist Leave-In Conditioner - Moisturizer & Curl Refresher | E33: Leave In | F33: =VLOOKUP(Summary!B33,'Shopify Catalog'!A:X,24,FALSE) -> 50 | H33: Moisture | I33: None | J33: High | K33: Medium | L33: Heat + Humidity | M33: No | N33: No | O33: No | P33: No | Q33: No | R33: No | S33: Yes | T33: Yes | U33: Yes | V33: Yes | X33: Damp | AA33: Stylers | AB33: Breahni Leave In Conditioner | AC33: No
B34: CAB-LCMR-237 | C34: Cachos Brazil | D34: Cachos Brazil Rio Mist Leave-In Conditioner - Moisturizer & Curl Refresher | E34: Leave In | F34: =VLOOKUP(Summary!B34,'Shopify Catalog'!A:X,24,FALSE) -> 75 | H34: Moisture | I34: None | J34: High | K34: Medium | L34: Heat + Humidity | M34: No | N34: No | O34: No | P34: No | Q34: No | R34: No | S34: Yes | T34: Yes | U34: Yes | V34: Yes | X34: Damp | AA34: Stylers | AB34: Breahni Leave In Conditioner | AC34: No
B35: CAM-RCM-237 | C35: Camille Rose | D35: Camille Rose Naturals Rose Cleansing Milk | F35: =VLOOKUP(Summary!B35,'Shopify Catalog'!A:X,24,FALSE) -> #N/A | H35: Moisture | I35: None | J35: All | K35: All | L35: Heat + Humidity | M35: No | N35: No | O35: No | P35: No | Q35: No | R35: No | S35: Yes | T35: Yes | U35: Yes | V35: Yes | X35: Wet | AA35: Conditioners | AB35: Innersense Hydrating Cream Hairbath | AC35: No
B36: CAM-DSM-237 | C36: Camille Rose | D36: =VLOOKUP(B36,'Shopify Catalog'!$A:$C,3,FALSE) -> Camille Rose Rosemary Strengthening Mist | F36: =VLOOKUP(Summary!B36,'Shopify Catalog'!A:X,24,FALSE) -> 65 | H36: Regrowth | I36: None | J36: Medium - High | K36: All | L36: Heat + Humidity | M36: No | N36: Yes | O36: Yes | P36: No | Q36: Yes | R36: Yes | S36: Yes | T36: Yes | U36: Yes | V36: Yes | X36: Dry | AA36: Stylers | AB36: Breahni Hydrating Refresher Spray | AC36: No
B37: CAM-HDLMR-237 | C37: Camille Rose | D37: =VLOOKUP(B37,'Shopify Catalog'!$A:$C,3,FALSE) -> Camille Rose Honey Dew - Liquid Moisture Refresher | F37: =VLOOKUP(Summary!B37,'Shopify Catalog'!A:X,24,FALSE) -> 75 | H37: Rehydrate | I37: None | J37: Low | K37: All | L37: Heat + Humidity | M37: No | N37: Yes | O37: No | P37: No | Q37: Yes | R37: Yes | S37: Yes | T37: Yes | U37: Yes | V37: Yes | X37: Dry | AA37: Stylers | AB37: Mielle Pomegranate & Honey Curl Refreshing Spray | AC37: Yes
B38: CAM-HSMS-237 | C38: Camille Rose | D38: =VLOOKUP(B38,'Shopify Catalog'!$A:$C,3,FALSE) -> Camille Rose Spiked Honey Mousse 4 in 1 Styler | F38: =VLOOKUP(Summary!B38,'Shopify Catalog'!A:X,24,FALSE) -> 75 | H38: Definition | I38: Soft | J38: All | K38: All | L38: Heat + Humidity | M38: No | N38: No | O38: No | P38: Yes | Q38: No | R38: No | S38: Yes | T38: Yes | U38: Yes | V38: Yes | X38: Damp | AA38: Leave In | AB38: The Doux Bee Girl Crazy Sexy Setting Foam | AC38: No
B39: CAM-HSMS-100 | C39: Camille Rose | D39: Camille Rose Spiked Honey Mousse 4 in 1 Styler | F39: =VLOOKUP(Summary!B39,'Shopify Catalog'!A:X,24,FALSE) -> 35 | H39: Definition | I39: Soft | J39: All | K39: All | L39: Heat + Humidity | M39: No | N39: Yes | O39: No | P39: No | Q39: No | R39: Yes | S39: Yes | T39: Yes | U39: Yes | V39: Yes | X39: Damp | AA39: Leave In | AB39: The Doux Bee Girl Crazy Sexy Setting Foam | AC39: No
B40: CAM-SHSD-56 | C40: Camille Rose | D40: =VLOOKUP(B40,'Shopify Catalog'!$A:$C,3,FALSE) -> Camille Rose Rosemary Oil Strengthening Hair & Scalp Drops | E40: Oil | F40: =VLOOKUP(Summary!B40,'Shopify Catalog'!A:X,24,FALSE) -> 65 | H40: Nourishment | I40: None | J40: High | K40: Thick | L40: Heat + Humidity | M40: No | N40: No | O40: No | P40: No | Q40: No | R40: Yes | S40: Yes | T40: Yes | U40: Yes | V40: Yes | X40: Dry & Damp | AA40: Stylers | AB40: Mielle Rosemary Mint Strengthening Oil Original | AC40: No
B41: CAM-OSLC-237 | C41: Camille Rose | D41: =VLOOKUP(B41,'Shopify Catalog'!$A:$C,3,FALSE) -> Camille Rose Rosemary Oil Strengthening Leave-In Conditioner | E41: Leave In | F41: =VLOOKUP(Summary!B41,'Shopify Catalog'!A:X,24,FALSE) -> 70 | H41: Moisture | I41: None | J41: High | K41: All | L41: Heat + Humidity | M41: No | N41: No | O41: No | P41: No | Q41: Yes | R41: Yes | S41: Yes | T41: Yes | U41: Yes | V41: Yes | X41: Damp | AA41: Stylers | AB41: Inahsi Aloe Hibiscus Leave In | AC41: No
B42: CAM-O5SM-351 | C42: Camille Rose | D42: =VLOOKUP(B42,'Shopify Catalog'!$A:$C,3,FALSE) -> Camille Rose Rosemary Oil 5 Minute Strengthening Hair Mask | F42: =VLOOKUP(Summary!B42,'Shopify Catalog'!A:X,24,FALSE) -> 75 | H42: Strength | I42: None | J42: High | K42: All | L42: Heat + Humidity | M42: No | N42: No | O42: No | P42: No | Q42: No | R42: No | S42: Yes | T42: Yes | U42: Yes | V42: Yes | X42: Wet | AA42: Treatments | AB42: Mielle Rosemay Mint Strengthening Hair Masque | AC42: No
B43: CAM-OSSC-351 | C43: Camille Rose | D43: =VLOOKUP(B43,'Shopify Catalog'!$A:$C,3,FALSE) -> Camille Rose Rosemary Oil Strengthening Hair & Scalp Cleanser | F43: =VLOOKUP(Summary!B43,'Shopify Catalog'!A:X,24,FALSE) -> 70 | H43: Strength | I43: None | J43: High | K43: All | L43: Heat + Humidity | M43: No | N43: No | O43: No | P43: No | Q43: Yes | R43: No | S43: Yes | T43: Yes | U43: Yes | V43: Yes | X43: Wet | AA43: Conditioners | AB43: Mielle Rosemary Mint Strengthening Shampoo | AC43: No
...

Sheet Reference Data
B2: For drop down options
B4: Brand | C4: Product Category | D4: Hold | E4: Porosity Suitability | F4: Density Suitability | G4: Climate Performance | H4: Build Up Risk | I4: Aloe | J4: Coconut | K4: Protein | L4: Humectant heavy | M4: Butter/Oil Heavy | N4: CG Approved | O4: Silicone Free | P4: Sulfate Free | Q4: Beginner Friendly | R4: Advanced User Product | S4: Best Seller
B5: As I Am | C5: Cleanser | D5: None | E5: All | F5: All | G5: Heat + Humidity | H5: Yes | I5: Yes | J5: Yes | K5: Yes | L5: Yes | M5: Yes | N5: Yes | O5: Yes | P5: Yes | Q5: Yes | R5: Yes | S5: Yes
B6: Breahni | C6: Detox | D6: Soft | E6: Low | F6: Fine | G6: Hard Water | H6: No | I6: No | J6: No | K6: No | L6: No | M6: No | N6: No | O6: No | P6: No | Q6: No | R6: No | S6: No
B7: Cachos Brazil | C7: Instant Conditioner | D7: Medium | E7: Low - Medium | F7: Medium
B8: Camille Rose | C8: Deep Conditioner | D8: Strong | E8: Medium | F8: Medium-Thick
B9: Curls | C9: Leave In | E9: Medium - High | F9: Thick
B10: Curls & Potions | C10: Treatment | E10: High
B11: Design Essentials | C11: Styler
B12: Ecoslay | C12: Oil
B13: Eden BodyWorks | C13: Scalp Treatment
B14: Healthy Hair Studio by Enitan
B15: Inahsi Naturals
B16: Innersense
B17: Innersense Beauty
B18: Jessicurl
B19: Kinky-Curly
B20: Mielle Organics
B21: Soultanicals
B22: Taliah Waajid
B23: Tangle Teezer
B24: TGIN
B25: The Doux
... B27: Uncle Funky's Daughter

Sheet Shopify Catalog
A1: SKU | B1: Handle | C1: Title | D1: Body (HTML) | E1: Vendor | F1: Product Category | G1: Type | H1: Tags | I1: Published | J1: Option1 Name | K1: Option1 Value | L1: Option1 Linked To | M1: Option2 Name | N1: Option2 Value | O1: Option2 Linked To | P1: Option3 Name | Q1: Option3 Value | R1: Option3 Linked To | S1: Variant SKU | T1: Variant Grams | U1: Variant Inventory Tracker | V1: Variant Inventory Policy | W1: Variant Fulfillment Service | X1: Variant Price | Y1: Variant Compare At Price | Z1: Variant Requires Shipping | AA1: Variant Taxable | AB1: Unit Price Total Measure | AC1: Unit Price Total Measure Unit | AD1: Unit Price Base Measure | AE1: Unit Price Base Measure Unit | AF1: Variant Barcode | AG1: Image Src | AH1: Image Position | AI1: Image Alt Text | AJ1: Gift Card | AK1: SEO Title | AL1: SEO Description | AM1: Google Shopping / Google Product Category | AN1: Google Shopping / Gender | AO1: Google Shopping / Age Group | AP1: Google Shopping / MPN | AQ1: Google Shopping / Condition | AR1: Google Shopping / Custom Product | AS1: Google Shopping / Custom Label 0 | AT1: Google Shopping / Custom Label 1 | AU1: Google Shopping / Custom Label 2 | AV1: Google Shopping / Custom Label 3 | AW1: Google Shopping / Custom Label 4 | AX1: Brand Button Url (product.metafields.custom.brand_button_url) | AY1: Brand Description (product.metafields.custom.brand_description) | AZ1: Brand Heading (product.metafields.custom.brand_heading) | BA1: How to use (product.metafields.custom.how_to_use) | BB1: Ingredients (product.metafields.custom.ingredients) | BC1: Google: Custom Product (product.metafields.mm-google-shopping.custom_product) | BD1: Product rating count (product.metafields.reviews.rating_count) | BE1: Age restrictions (product.metafields.shopify.age-restrictions) | BF1: Event type (product.metafields.shopify.event-type) | BG1: Hair care finish (product.metafields.shopify.hair-care-finish) | BH1: Hair care items included (product.metafields.shopify.hair-care-items-included) | BI1: Hair type (product.metafields.shopify.hair-type) | BJ1: Hold level (product.metafields.shopify.hold-level) | BK1: Product form (product.metafields.shopify.product-form) | BL1: Target gender (product.metafields.shopify.target-gender) | BM1: Ticket type (product.metafields.shopify.ticket-type) | BN1: Complementary products (product.metafields.shopify--discovery--product_recommendation.complementary_products) | BO1: Related products (product.metafields.shopify--discovery--product_recommendation.related_products) | BP1: Related products settings (product.metafields.shopify--discovery--product_recommendation.related_products_display) | BQ1: Search product boosts (product.metafields.shopify--discovery--product_search_boost.queries) | BR1: Variant Image | BS1: Variant Weight Unit | BT1: Variant Tax Code | BU1: Cost per item | BV1: Status
A2: =S2 -> SCE-SCED-LMP | B2: summer-curl-edit-dew | C2: Summer Curl Edit – Dew | Low to Medium Porosity Curl Ritual | D2: <p>Your answer to summer styling without the weight.<br>Dew is your low to medium porosity ritual—crafted for curls that resist moisture, frizz easily, and fall flat in the heat.</p> <p>Inside this editorial curation, you'll find a humidity-proof layering system designed to hydrate without heaviness, define without crunch, and hold without buildup.</p> <p>Each product is meticulously selected for its lightweight texture, ingredient harmony, and climate-specific performance under Middle Eastern heat. It’s curation, not guesswork.</p> <p> </p> <p>What's inside:</p> <p>1 X Uncle Funky's Daughter Midnite Train Leave In (8oz)</p> <p>1 X Kinky Curly Knot Today Leave In (8oz)</p> <p>1 X The Doux Mousse Def Texture Foam (7oz)</p> <p>1 X TreLuxe Hi Definition Styling Gel (8oz)</p> | E2: Emerson | F2: Health & Beauty > Personal Care > Hair Care > Hair Styling Products | H2: Aloe Vera, Best seller, bestseller, Bestsellers, Bundle, Bundle Set, CG Approved, CGM, CGM Approved, curl protection, Curly Hair, Frizz Free, Hair Growth & Length Retention, Low Porosity Essentials, Moisture Rich, Natural, Natural Hair, Protein Free, Styler, Sulfate - Free, Summer Curl Edit - Dew, Summer Essential | I2: FALSE | J2: Title | K2: Default Title | S2: SCE-SCED-LMP | T2: 3000 | U2: shopify | V2: deny | W2: manual | X2: 320 | Y2: 0 | Z2: TRUE | AA2: TRUE | AG2: https://cdn.shopify.com/s/files/1/0504/5187/3989/files/8.jpg?v=1751428670 | AH2: 1 | AJ2: FALSE | AL2: Your low to medium porosity summer curl solution. Lightweight, frizz control, long-lasting hold—even in 45° heat. Limited release. Shop Dew while it lasts. | AY2: Expertly paired curl rituals for hair that thrive. Each curation is handpicked and tested for performance, so you get results, not just products. No overwhelm. Just proven formulas that work beautifully together. | AZ2: Emerson | BA2: See individual product pages | BB2: See individual product pages | BD2: 1 | BS2: kg | BU2: 162.43 | BV2: draft
A3: =S3 -> SCE-SCEQ-HPC | B3: summer-curl-edit-quench | C3: Summer Curl Edit – Quench | High Porosity Curl Ritual | D3: <p>For curls that thirst and frizz.<br>Quench is your high-porosity ritual—designed to saturate dry strands, seal in moisture and sculpt definition that survives the Gulf summer.</p><br> <p>This is your moisture-rich curation for bounce, elasticity, and hold that doesn’t quit.</p> <p>Engineered for performance and indulgence, this edit layers hydrating and sealing formulas that work in tandem to protect against breakage, reduce porosity stress and create long-lasting curl memory.</p><br> <p>What's inside:</p> <p>1x The Doux Fast Forward Conditioner (8oz)</p> <p>1x TréLuxe Aloe Vera Curl Primer (8oz)</p> <p>1x Uncle Funky’s Daughter Curly Magic (18oz)</p> <p>1x Innersense I Create Hold (10oz)</p> | E3: Emerson | F3: Health & Beauty > Personal Care > Hair Care > Hair Styling Products | H3: Aloe Vera, Best seller, bestseller, Bestsellers, Bundle Set, CG Approved, CGM, CGM Approved, Chemically Treated Hair, Colour Safe, curl protection, Curly Hair, Frizz Free, High Porosity Essentials, Moisture Rich, Natural, Natural Hair, New Arrivals, Protein Free, Styler, Sulfate - Free, Summer Curl Edit, Summer Curl Edit – Quench, Summer Essential | I3: FALSE | J3: Title | K3: Default Title | S3: SCE-SCEQ-HPC | T3: 3000 | U3: shopify | V3: continue | W3: manual | X3: 369 | Y3: 0 | Z3: TRUE | AA3: TRUE | AG3: https://cdn.shopify.com/s/files/1/0504/5187/3989/files/8.jpg?v=1751428670 | AH3: 1 | AJ3: FALSE | AL3: Your high porosity summer curl solution. Deep moisture, frizz control, long-lasting hold—even in 45° heat. Limited release. Shop Quench while it lasts. | AY3: Expertly paired curl rituals for hair that thrive. Each curation is handpicked and tested for performance, so you get results, not just products. No overwhelm. Just proven formulas that work beautifully together. | AZ3: Emerson | BA3: See individual product pages | BB3: See individual product pages | BD3: 1 | BS3: kg | BU3: 186.8 | BV3: draft
A4: =S4 -> M&M-LMP | B4: mummy-me-kit-low-to-medium-porosity | C4: Mummy & Me Kit - Low to Medium Porosity | D4: <p>Support delicate curls with care and consistency.</p> <p><span class="s2">Curated especially for little ones with low to medium porosity hair, this gentle yet effective ritual supports strands that resist moisture but retain it once it’s sealed in. Each product has been handpicked to soften strands</span><span class="s1">, encourage moisture penetration, reduce frizz, and deliver long lasting nourishment without heaviness or build up.</span></p> <p>Whether you’re learning your child’s hair together or already in your groove, this set empowers you to care with confidence.<br><span class="s2"></span></p> <p>What’s inside:</p> <p>1 X Camille Rose Sweet Cleansing Rinse </p> <p>1 X Camille Rose Conditioning Custard</p> <p>1 X Camille Rose Sundae Glaze Leave In</p> <p>1 X Breahni Light Styling Gel</p> | E4: Emerson | F4: Uncategorized | H4: Best seller, Bundle, Bundle Set, CG Approved, CGM Approved, Curl Definer, Curl Defining, Curl defining gel, Curl Defining Leave-in, Curl definition, Hair Styling, Kid Safe, Kinky Curl Knot Today, Kinky Curly, Kinky Curly Knot Today, Knot Today, Styler, Styling, Styling Custard, The Mummy & Me Edit | I4: TRUE | J4: Title | K4: Default Title | S4: M&M-LMP | T4: 1500 | U4: shopify | V4: deny | W4: manual | X4: 225.25 | Y4: 265 | Z4: TRUE | AA4: TRUE | AG4: https://cdn.shopify.com/s/files/1/0504/5187/3989/files/05C20F6E-68CC-48BF-96CF-5DE5A14357D4.jpg?v=1749913912 | AH4: 1 | AJ4: FALSE | AY4: Expertly paired curl rituals for hair that thrive. Each curation is handpicked and tested for performance, so you get results, not just products. No overwhelm. Just proven formulas that work beautifully together. | AZ4: Emerson | BA4: See individual product pages. | BB4: See individual product pages. | BS4: kg | BV4: active
A5: =S5 -> DUO-8BG-355 | B5: the-doux | C5: The Doux 808 Base Gel | D5: <div class="content-block product-rte rte"> <div class="content-slide-content" data-height=""> <div id="liquid-liquid_QY683U" class="content-slide-space variant_metafields"> <p class="whitespace-normal break-words">Drop the base and watch your curls go boom. 808 Base Gel lays down the foundation for every curl style in your rotation – from wash-and-gos to twist-outs. This medium-hold gel brings the bass line your curls need to stay defined and frizz-free all day.</p> </div> </div> </div> <p>808 Base Gel is the beat drop your curls have been waiting for. Like its namesake bass drum that anchors every track, this gel creates the foundation that makes your whole style hit different.</p> <p>The medium-hold formula strikes that perfect balance – strong enough to lock in your pattern but flexible enough to keep curls bouncy and touchable. While other gels leave you crunchy or flaky, 808 keeps it smooth with a formula that defines without the drama. It's built to be your first layer, creating a frizz-fighting base that other products can build on.</p> <p>Use it solo for simple, defined curls or stack it under MOUSSE DEF for next-level volume and hold. Your wash-and-go just got more reliable, your twist-out more defined, and your TWA more popping. This is the gel that turns good curl days into great ones – because every masterpiece starts with a solid foundation.</p> <p>Frizz trying to remix your style? Not happening.</p> <p>Definition falling flat by midday? 808's got the stamina.</p> <p>Your curls about to stay fresh from morning meeting to midnight.</p> | E5: The Doux | F5: Health & Beauty > Personal Care > Hair Care > Hair Styling Products | G5: Styler | H5: Base Gel, Bouncy curls, CG Approved, CG Method, cgapproved, CGM Approved, Curl Defining, Curl definition, Curly Hair, Frizz control, Frizz Free, Gel, Medium Hold, Natural, Natural Gel, Natural Hair, Styler, Styling, Styling Gel, Sulfate - Free, The Doux, Twist out, Wash- n -go | I5: TRUE | J5: Size | K5: 12 oz | S5: DUO-8BG-355 | T5: 560 | U5: shopify | V5: deny | W5: manual | X5: 75 | Z5: TRUE | AA5: TRUE | AG5: https://cdn.shopify.com/s/files/1/0504/5187/3989/files/808N_eb8317d9-b065-4ba2-b06a-75c5d2d0d5f1.png?v=1755075993 | AH5: 1 | AI5: The Doux 808 Base Gel | AJ5: FALSE | AL5: Discover The Doux 808 Base Gel in the UAE. A medium hold base gel for layering, flexible curl defining & Fights frizz. Perfect for all curl types & textures | AM5: 1901 | AY5: The Doux is an award winning brand of super-fresh, texture focused solutions inspired by the life of a stylist and love for the culture. Merging old-school flava with new-school science. The Doux developed a range of simple, multi-functional formulas designed to put an end to the complicated regimens and conflicting information that are shattering your confidence. | AZ5: The Doux | BA5: WET IT: Start with soaking wet hair (water is your friend)<br> APPLY IT: Apply in sections, letting curls clump naturally.<br> ROCK IT: Rock it solo or layer MOUSSE DEF on top for extra hold.<br> DIFFUSE IT: Diffuse until 100% dry for maximum bounce.<br> FLUFF IT: Fluff from the roots and let them curls live.<br> THE BASE: 808 always goes first – it's the base, remember? No oils or creams before this gel. Let it do its job as the foundation, then build your style from there.<br> | BB5: Aloe Barbadensis Leaf Juice Powder, Water (Aqua), Cetearyl Alcohol, Behentrimonium Methosulphate, C13-15 Alkane, Cetrimonium Chloride, Butyrospermum Parkii (Shea) Butter, Simmondsia Chinensis (Jojoba) Seed Oil, Butylene Glycol, Aminoethylaminopropyl Dimethicone, Polyquaternium-37, PPG-1 Trideceth-6, Propylene Glycol Dicaprylate/Dicaprate, Stearalkonium Chloride, Aloe Vera Callus Extract (Stem Cell), Hydrolyzed Vegetable Protein PG-Propyl Silanetriol, Ananas Sativus (Pineapple) Fruit Extract, Glycerin, Phenethyl Alcohol, Fragrance, Hydrolyzed Quinoa, Cereus Grandiflorus (Cactus) Flower Extract, Hydrolyzed Soy Protein, Tocopheryl Acetate, Caprylhydroxamic Acid, Arginine, Brassica Campestris/Aleurites Fordi Oil Copolymer, Aspergillus Ferment, Disodium EDTA, Lactic Acid, Alanine , Aspartic Acid , Glutamic Acid, Histidine, Isoleucine, Leucine, Lysine, Phenylalanine, Proline, Serine, Threonine, Tyrosine, Valine | BN5: the-doux-big-poppa-defining-gel; the-doux-mousse-def-texture-foam | BP5: only manual | BR5: https://cdn.shopify.com/s/files/1/0504/5187/3989/files/808N_eb8317d9-b065-4ba2-b06a-75c5d2d0d5f1.png?v=1755075993 | BS5: kg | BU5: 35.2 | BV5: active
A6: =S6 -> DUO-BEHG-355 | B6: the-doux-bananas-xtreme-hold-hair-gel | C6: The Doux Bananas Xtreme Hold Hair Gel | D6: <p><span>This hold is bananas, B-A-N-A-N-A-S! The Bananas Xtreme hold Hair Gel is the extreme styler that locks your look down tighter than Fort Knox.</span></p> <p>BANANAS XTREME HOLD HAIR GEL said "let's go crazy" and meant every word. This isn't playing around with medium hold – we're talking extreme, unbreakable, your-hair-isn't-moving-till-you-say-so kind of control.</p> <p>Whether you're sculpting glass-hair sleek edges, creating gravity-defying spikes that salute the sky, or slicking back a style so smooth it looks like liquid, BANANAS delivers that professional-strength hold.</p> <p>The formula brings serious grip without the helmet head effect – your style stays locked but doesn't feel like concrete. Perfect for when you need your hair to stay exactly where you put it, no questions asked. From intricate designs to simple slick-backs, from defined curls to sculptural styles, this gel has the muscle to make it happen.</p> <p>And here's where it gets bananas – when you're ready to switch it up, just add water and watch it reactivate like magic.</p> <p>No flaking, no residue, just extreme hold that goes hard but stays flexible enough to rework. Your style game is about to go absolutely bananas.</p> | E6: The Doux | F6: Health & Beauty > Personal Care > Hair Care > Hair Styling Products | G6: Styler | H6: CG Approved, CG Method, cgapproved, CGM, CGM Approved, Colour Safe, Curl Definer, Curl Defining, Curl definition, curls, Curly Hair, Frizz control, Frizz Free, Hair Styling, Kid Safe, Natural, Natural Hair, Styler, Styling, Styling Gel, Xtreme Hold | I6: TRUE | J6: Size | K6: 12 oz | S6: DUO-BEHG-355 | T6: 0 | U6: shopify | V6: deny | W6: manual | X6: 85 | Z6: TRUE | AA6: TRUE | AF6: 850031703902 | AG6: https://cdn.shopify.com/s/files/1/0504/5187/3989/files/EF045710-ED5F-4FB3-A306-699C24D37D4E.webp?v=1754305163 | AH6: 1 | AI6: The Doux Bananas Gel Available in Dubai, UAE | Emerson Hair & Beauty | AJ6: FALSE | AL6: Discover The Doux Bananas Xtreme Hold Gel: A strong hold gel that defines curls without flaking, humid resistant, controls frizz, nourishes edges & locks in style | AY6: The Doux is an award winning brand of super-fresh, texture focused solutions inspired by the life of a stylist and love for the culture. Merging old-school flava with new-school science. The Doux developed a range of simple, multi-functional formulas designed to put an end to the complicated regimens and conflicting information that are shattering your confidence. | AZ6: The Doux | BA6: WET IT: Drench hair thoroughly – this gel loves water. <br> APPLY IT: Get generous from roots to ends, no skimping. <br> DEFINE IT: Shingle or finger coil for curls that pop off.<br> DRY IT: Diffuse or sit under the dryer until 100% dry. <br> STYLE IT: Fluff and separate once completely dry. <br> REACTIVATE IT: Spritz with water to rework anytime. <br> | BB6: Water (Aqua), PVP, Propanediol, Maltodextrin/VP Copolymer, Sorbitol, Acrylates Copolymer, Honey, Aminomethyl Propanol, Acrylates/C10-30 Alkyl Acrylate Crosspolymer, Aloe Barbadensis Leaf Juice, Musa Sapientum (Banana) Fruit Extract, Tocopheryl Acetate, Panthenol, Silk Amino Acids, Sodium Hyaluronate, Ascorbic Acid, Phenoxyethanol, Ethylhexylglycerin, Helianthus Annus (Sunflower) Seed Oil Lactic Acid, Fragrance (Parfum), Yellow 5 (CI 19140) | BN6: the-doux-fast-forward-heat-prep-conditioner; the-doux-press-rewind-curl-rentention-shampoo | BP6: ahead | BS6: kg | BU6: 37.43 | BV6: active
A7: =S7 -> MIE-MMTHS | B7: mielle-mongongo-oil-thermal-heat-protectant-spray-not-so-perfect | C7: Mielle Mongongo Oil Thermal & Heat Protectant Spray -(Not So Perfect) | D7: <p><strong>** Product content is full - however the lid is broken**</strong></p> <p>Do you use heat in your styling routine? Protect your hair with Mielle's all-natural protectant spray</p> <p>• Provides Intense Heat Defense™ and Curl Pattern Protection™<br>• Protects against high-heat styling<br>• Made without parabens, preservatives, or harmful chemicals</p> | E7: Mielle Organics | F7: Health & Beauty > Personal Care > Hair Care > Hair Styling Products | G7: Moisturizers & Leave - Ins | H7: Blowdrying spray, CG Approved, CG Method, cgapproved, CGM, CGM Approved, Chemically Treated Hair, Frizz control, Hair SPF, Heat Protectant, Heat Protector, High Porosity, Kid Safe, Mielle, Mielle Organics, Natural Hair, Sulfate - Free | I7: FALSE | J7: Size | K7: 4 oz | S7: MIE-MMTHS | T7: 340 | U7: shopify | V7: deny | W7: manual | X7: 0 | Z7: TRUE | AA7: TRUE | AJ7: FALSE | AM7: 1901 | AY7: Mielle Organics a natural haircare brand that delivers on its promises of healthier, stronger and more hydrated hair through use of organic ingredients, products have been uniquely formulated to deliver hydration, moisture and definition.<br> | AZ7: Mielle Organics | BA7: After shampooing apply to clean, wet hair and gently comb through from roots to ends.<br> Proceed with desired heat styling. Avoid eye contact. Keep out of reach of children. | BB7: Water (Aqua, Eau), Cetearyl Alcohol, Polysorbate 60, Amodimethicone, Cetrimonium, Chloride, Trideceth-12, Glycerin,Propylene Glycol, Peg-12 Dimethicone, Polysorbate-20, PVP, Prunus Amygdalus Dulcis (Sweet Almond) Oil, Plukenetia Volubilis (Sacha Inchi) Seed Oil, Argania Spinosa (Argan) Kernel Oil, chinziophyton Rautanenii (Mongongo) Kernel Oil, Vitis Vinifera (Grape) Seed Oil, Disodium EDTA, Tocopheryl, Acetate, Cyclopentasiloxane, Dimethiconol, Hydrolyzed Wheat Protein, Fragrance (Parfum), Phenoxyethanol, Benzoic Acid, Ethylhexylglycerin, Glycereth-2 Cocoate | BS7: kg | BU7: 25.65 | BV7: draft
A8: =S8 -> AIM-JBOHM-237 | B8: as-i-am-jamaican-black-castor-oil-hair-mask | C8: As I Am Jamaican Black Castor Oil Hair Mask | D8: <p class="MsoNormal">Enrich dehydrated hair with an intense therapy hair mask. This rich, creamy treatment moisturizes, detangles and conditions hair. Provides long-lasting hydration. Restores and repairs your hair health. Use to soften hair, ease combing, treat dry scalps.</p> | E8: As I Am | F8: Health & Beauty > Personal Care > Hair Care > Hair Care Kits | G8: Treatment | H8: CG Approved, CG Method, cgapproved, CGM, CGM Approved, Curly Hair, Deep conditioning masque, Detangling, Dry scalp, Hair Mask, Hair Masque, Hair Masque Treatment, Hair restorator, Hair Treatment, Hydrating, Hydrating Mask, Hydration, Moisture Rich, Natural, Natural Hair, Scalp Care, Sulfate - Free | I8: TRUE | J8: Size | K8: 8 oz | S8: AIM-JBOHM-237 | T8: 440 | U8: shopify | V8: deny | W8: manual | X8: 75 | Z8: TRUE | AA8: TRUE | AF8: 858380040150 | AG8: https://cdn.shopify.com/s/files/1/0504/5187/3989/files/453A048A-5B00-4F1D-8817-AC7DC51BBB5F.png?v=1745307994 | AH8: 1 | AI8: As I Am Jamaican Black Castor Oil Hair Mask | AJ8: FALSE | AL8: A creamy treatment enrich with moisturizer and detangler that provides a long lasting hydration. Helps to restore and repair the hair and treat hair scalp. It helps to soften the hair while combing. | AM8: 8452 | AY8: As I Am products consists of wonderfully formulated products designed specifically for; curly and tightly coiled hair; each with an impressive ingredient listing that includes many of nature's finest organic ingredients. <p>Perfect for Type 3 & 4 Hair Types.</pr> | AZ8: As I Am | BA8: Apply a generous amount to hair strands and working the product from root to tip <br> Leave it on for 15-20 minutes <br> Rinse well. | BB8: Aqua/water/eau, Hydrogenated vegetable oil, Cetearyl alcohol, Cetyl alcohol, Betaine, Ricinus communis (castor) seed oil, Ascorbic acid, Linum usitatissimum (linseed) seed extract, Ceramide ng, Glycerin, Tocopherol, Stearamidopropyl dimethylamine, Behentrimonium chloride, Quaternium-80, Propanediol, Fragrance/parfum, Phenoxyethanol, Citric acid, Polyquaternium-37, Dipropylene glycol, Caprylyl glycol, Isostearyl ethylimidazolinium ethosulfate, Propylene glycol dicaprylate/dicaprate, Piroctone olamine, Polyacrylamide, Laureth-9, Peg-8, Ppg-1 trideceth-6, Sodium lauroyl lactylate, Peg-100 stearate, Hydroxypropyl bispalmitamide mea, Peg-3 distearate, Sodium lauroyl glutamate, Cocamidopropyl betaine, Sodium cocoyl isethionate, Ceteareth-25, Sodium benzoate, Potassium sorbate, Sodium chloride, Amyl cinnamal, Hexyl cinnamal, Limonene | BS8: kg | BU8: 28.63 | BV8: active
A9: =S9 -> DUO-BGHCC-473 | B9: the-doux-bee-girl-honey-curl-custard | C9: The Doux Bee Girl Honey Curl Custard | D9: <div class="easyslider-item easyslider-active" data-es-marker="slide-mist-demeanor-super-charged-honey-shine-mist-3" data-es-handle="slide-what-it-doux"> <div class="easyslider-content" aria-expanded="true" aria-hidden="false" aria-labelledby="easyslider-label-7527090290910-0" role="tabpanel"> <div class="easyslider-content-wrapper"> <p><span>Meet the custard that doesn’t just style your curls - it revives them. </span>This luxurious, honey-infused formula drenches even the tightest coils in lasting hydration while sculpting definition that feels soft to the touch - never crunchy, never flaking. <br><br>The secret? Super-charged honey with a positive charge that smooths the cuticle, locks in moisture, and ignites mirror-like shine.<br><span></span></p> <p>Every scoop is fortified with Aloe and powerhouse vitamins B, C &amp; E to protect growth, while Keratin and Silk Amino Acids wrap each strand in strength and bounce. The result: curls that spring, move, and glow with confidence - juicy, touchable, alive.<br><span></span></p> <p> </p> <p><span>Because thirsty curls don’t just need control</span></p> </div> </div> </div> | E9: The Doux | F9: Health & Beauty > Personal Care > Hair Care > Hair Styling Products | G9: Styler | H9: CG Approved, CG Method, cgapproved, CGM, CGM Approved, Curl Defining, Curl Defining Custard, Curl definition, Curling Custard, Curly Hair, Hair Styling, Natural, Natural Hair, Soft Hold, Styler, Styling, Styling Custard, Styling Gel, Sulfate - Free, The Doux | I9: TRUE | J9: Size | K9: 16 oz | S9: DUO-BGHCC-473 | T9: 0 | U9: shopify | V9: deny | W9: manual | X9: 75 | Z9: TRUE | AA9: TRUE | AG9: https://cdn.shopify.com/s/files/1/0504/5187/3989/files/3AF0A611-7EF1-4606-92F2-33B29B96EF11.webp?v=1750222328 | AH9: 1 | AI9: The Doux Bee Girl Honey Curl Custard | AJ9: FALSE | AK9: The Doux Bee Girl Honey Curl Custard | AL9: Discover the Doux Bee Girl Honey Curl Custard: A soft hold curl defining custard that hydrates, defines even the tightest curls with no crunch/flakes. | AM9: 1901 | AY9: The Doux is an award winning brand of super-fresh, texture focused solutions inspired by the life of a stylist and love for the culture. Merging old-school flava with new-school science. The Doux developed a range of simple, multi-functional formulas designed to put an end to the complicated regimens and conflicting information that are shattering your confidence. | AZ9: The Doux | BA9: Apply to clean, wet hair in small sections. Rake through with fingers to clump curls. Hood dry or diffuse until 100% dry. Fluff to the gods or as desired. | BB9: AQUA (WATER, EAU), PROPANEDIOL, ACRYLATES COPOLYMER, MALTODEXTRIN/VP COPOLYMER, SORBITOL, PVP, AMINOMETHYL PROPANOL, PARFUM (FRAGRANCE), ACYLATES/C1030 ALKYL ACRYLATE CROSSPOLYMER, PHENOXYETHANOL, HYDROXYPROPYLTRIMONIUM HONEY, MEL (HONEY, MIEL), PANTHENOL, SODIUM HYALURONATE, KERATIN AMINO ACIDS, SILK AMINO ACIDS, ASCORBIC ACID, TOCOPHERYL ACETATE, ALOE BARBADENSIS LEAF JUICE, LACTIC ACID, ETHYLHEXYLGLYCERIN. | BN9: the-doux-crazy-sexy-curl-honey-setting-foam; curls-blueberry-bliss-curl-control-jelly; curls-blueberry-bliss-hair-growth-oil | BP9: only manual | BR9: https://cdn.shopify.com/s/files/1/0504/5187/3989/files/3AF0A611-7EF1-4606-92F2-33B29B96EF11.webp?v=1750222328 | BS9: kg | BU9: 30.78 | BV9: active
A10: =S10 -> UFD-SBTDM-222 | B10: uncle-funkys-daughter-soul-bounce-texture-defining-mousse | C10: Uncle Funky's Daughter Soul Bounce Texture Defining Mousse | D10: <p>Lock in hold, boost shine, amplify volume and define texture with Uncle Funky's Daughter honey, quinoa &amp; keratin formulated texture defining mousse. Pairs well with top selling Curly Magic for amazing results.</p> <p> </p> | E10: Uncle Funky's Daughter | F10: Health & Beauty > Personal Care > Hair Care > Hair Styling Products | G10: Styler | H10: CG Approved, CG Method, cgapproved, CGM, CGM Approved, Curl Definer, Curl defining mousse, Curl definition, Curly Hair, cury hair, Hair volume, Mousse, Natural, Natural Hair, Styler, Styling Mousse, Sulfate - Free, Summer Curl Edit, Volumizing foam | I10: TRUE | J10: Size | K10: 7.5 oz | S10: UFD-SBTDM-222 | T10: 440 | U10: shopify | V10: deny | W10: manual | X10: 80 | Z10: TRUE | AA10: TRUE | AF10: 856681006561 | AG10: https://cdn.shopify.com/s/files/1/0504/5187/3989/files/4B28B776-F7B4-4D84-A121-344C06024716.jpg?v=1744365128 | AH10: 1 | AI10: Uncle Funky's Daughter Soul Bounce Texture Defining Mousse | AJ10: FALSE | AL10: Lock in hold, boost shine, amplify volume and define texture with Uncle Funky's Daughter honey mousse, quinoa & keratin formulated texture defining mousse. It create a touchable hold which enhances shine and texture without crunch or build-up. Weather you are setting styling, enhancing curls or adding volume this mousse gives a flawless result. | AM10: 1901 | AY10: Enjoy this range of naturally formulated products crafted to satisfy every curl and enhance and celebrate your natural curl pattern. <br> This range includes the infamous Curly Magic Curl Stimulator. Uncle Funky's Daughter also commonly known as UFD is created with the finest natural ingredients to promote moisture, hydration, curl formation and curl protection.<br> | AZ10: Uncle Funky's Daughter | BA10: Divide freshly cleansed and conditioner hair into sections. Apply a liberal amount to wet or dry hair combing or fingering through from root to end. Style as desired. Allow hair to dry naturally or use a diffuser or hood dryer. How it works: This fast drying, texture-defining mousse locks in long-lasting hold, boosts shine, amplifies volume, and enchances texture & definition. | BB10: Water (Aqua), Honey (Mel), Oleth-20, Cocamidopropyl Betaine, Polyquaternium-55, PVP, Fragrance, (Parfum), Phenoxyethanol, Ethylhexylglycerin, Polysorbate 20, Hydrolyzed Quinoa, Hydrolyzed Keratin, Tocopheryl Acetate, Citric Acid, Disodium EDTA. | BN10: camille-rose-curl-maker; uncle-funkys-daughter-curly-magic | BP10: only manual | BS10: kg | BU10: 29.6 | BV10: active
A11: =S11 -> TRX-AVCP-237 | B11: treluxe-soothe-restore-aloe-vera-curl-primer | C11: TréLuxe Aloe Vera Curl Primer | D11: <p>Save time on washday, and throughout the week! TréLuxe innovative Aloe Vera Curl Primer:</p> <p><span style="font-weight: 400;">✔️</span>reduces detangling time by up to 70%,</p> <p><span style="font-weight: 400;">✔️</span>smooths and defines curls for easier application of styling products,</p> <p><span>✔️</span>reduces the amount of water needed to refresh curls between wash days,</p> <p><span>✔️</span>decreases drying time without sacrificing moisture.</p> <p>This is the beginning of long-lasting, frizz-free curl definition that you no longer have to work for!</p> <p><span style="font-weight: 400;"><strong>How it works:</strong><span> </span>The primer's plant-based ingredients help smooth, detangle, moisturize, and soften your waves and curls to extend wash day results, and save time when refreshing. The extreme slip makes detangling a breeze; and well-defined curls are quickly served up without weighing down delicate strands, due to the lightweight formula. </span></p> <p><span style="font-weight: 400;"><strong>Can be used as</strong><span> </span>a: Pre-Style Primer | Pre-poo Detangler | Moisturizing/Curl Clumping Refresher </span></p> | E11: TréLuxe | F11: Uncategorized | G11: Moisturizers & Leave - Ins | H11: Aloe Vera, CG Approved, CG Method, CGM, CGM Approved, Curl clumping refresher, Curl Defining, Curl definition, Curl primer, curls, Curly Hair, detangler, Hair Primer, High Porosity Essentials, Hydrating, Moisturizer, Natural, Natural Hair, New Arrivals, Treluxe, Vegan, Vegan Hair Care | I11: TRUE | J11: Size | K11: 8 Fl oz | S11: TRX-AVCP-237 | T11: 440 | U11: shopify | V11: deny | W11: manual | X11: 95 | Z11: TRUE | AA11: TRUE | AF11: 851533006065 | AG11: https://cdn.shopify.com/s/files/1/0504/5187/3989/files/AEF5802C-35D7-4E1A-90E5-8A82F2402369.png?v=1741151047 | AH11: 1 | AI11: TréLuxe Aloe Vera Curl Primer | AJ11: FALSE | AY11: TréLuxe products were created to solve the curly hair woes of dryness, frizz, weak strands, and dull hair using premium quality natural ingredients and Active Botanical blends that moisturize, strengthen, and define curly and wavy hair.<br> No parabens, No silicones, No phthalates, No sulfates, No artificial colors, Gluten-free, Cruelty-free | AZ11: TréLuxe | BA11: On Wash Day: <br> cleanse and rinse hair and scalp, optional: apply Untie the Knot Nourishing Leave-In Conditioner if hair is prone to dryness and more moisture is needed while hair is still wet, apply Aloe Vera Curl Primer to your waves or curls, starting with a quarter sized amount. <br> <br> Evenly distribute product through hair to detangle knots and smooth strands. apply styling product(s) <br> <br> To Refresh between Wash Days:<br> <br> Apply to dry, damp, or wet hair, to increase moisture and define curls between wash days. <br> <br> Evenly distribute product through hair *Aloe Vera Curl Primer can be left on, or rinsed out. <br> <br> **Best used on hair and scalp that is cleansed at least once per week. <br> | BB11: Water (Aqua), Aloe Barbadensis (Aloe Vera) Leaf Juice, Glycerin, PEG-40 Hydrogenated Castor Oil, Ascorbic Acid (Vitamin C), Polyquaternium-37, Tocopheryl (Vitamin E) Acetate, Menthyl Ethylamido Oxalate, Hydrogenated Castor Oil/Sebacic Acid Copolymer, Sorbitol, Guar Hydroxypropyltrimonium Chloride, Citric Acid, Potassium Sorbate, Sodium Benzoate, Polysorbate 20, PEG-45m, Fragrance (Parfum), Phenoxyethanol, Caprylyl Glycol, Sorbic Acid | BS11: kg | BU11: 42.02 | BV11: active
A12: =S12 -> UFD-UCUGK | B12: uncle-funkys-daughter-ultimate-kinky-curly-discovery-kit | C12: Uncle Funky's Daughter Ultimate Curly Girls Kit | D12: <p><strong>Best Sellers Sample Pack </strong></p> <p>The best-selling Uncle Funky Daughter’s products together at last! </p> <p>Pack includes 1 bottle each of Midnite Train Leave-in Conditioner, Supercurl Miracle Moisture Crème, Extra Butter Curl Forming Crème, Curly Magic Curl Stimulator, and Thirsty Curls Leave-In Curl Revitalizer, all in 2 ounce trial sizes.</p> <p><strong>How it works</strong></p> <ul> <li>Midnite Train strengthens tresses and promotes growth</li> <li>Supercurl stretches curls, adds shine &amp; hydrates</li> <li>Extra Butter creates definition &amp; shine for lasting styles</li> <li>Curly Magic provides a firm hold, shine &amp; definition</li> <li>Thirsty Curls revives the bounce in frizzy, fallen curls</li> </ul> | E12: Uncle Funky's Daughter | F12: Uncategorized | G12: Hair care | H12: Bundle Set, CG Approved, CGM, CGM Approved, Colour Safe, Curl Defining, Curl definition, curls, Curly Hair, discovery kit, Hair Styling, Hydrating Conditioner, Kid Safe, leave-in Conditioner, Mini, Mini Size, Moisture Rich, Natural, Natural Hair, Styler, Styling, Styling Cream, Sulfate - Free, Travel Kit | I12: TRUE | J12: Size | K12: 2 oz | S12: UFD-UCUGK | T12: 1200 | U12: shopify | V12: deny | W12: manual | X12: 100 | Z12: TRUE | AA12: TRUE | AF12: 861916000122 | AG12: https://cdn.shopify.com/s/files/1/0504/5187/3989/files/FED42630-563E-48E4-9FE6-B96BDF6E9DE9.png?v=1739809064 | AH12: 1 | AI12: Uncle Funky's Daughter Midnite Train, Supercurl, Extra Butter, Curly Magic and Thirsty Curls | AJ12: FALSE | AL12: Now in one convenient trial-size bundle! Your uncle funky's daughter product perfect for trying, travelling or gifting. This pack houses the 5 best selling curl essentials of 2oz each which provide stretcjes curls, add shine, delivers intense hydration, provide firm hold and frizz control | AY12: Enjoy this range of naturally formulated products crafted to satisfy every curl and enhance and celebrate your natural curl pattern. <br> This range includes the infamous Curly Magic Curl Stimulator. Uncle Funky's Daughter also commonly known as UFD is created with the finest natural ingredients to promote moisture, hydration, curl formation and curl protection.<br> | AZ12: Uncle Funky's Daughter | BA12: Directions Step 1: Lightly Spray the Scalp & Hair with Midnite Train Leave-in Conditioner Step 2: Type 3 Naturals: Apply Supercurl Miracle Moisture Crème from Root to Ends in Sections| Type 4 Naturals: Apply Extra Butter Brilliant Shine Crème from Root to Ends in Sections Step 3: Apply Curly Magic Curl Stimulator in Sections from Root to End (Note: A Little Dap Will Do Ya!) Step 4: Style as Desired. Diffuse or Air Dry Day 2 or 3: Lightly Spray Thirsty Curls Revitalizer Spray onto Tresses to Revive Curls | BB12: Midnite Train: Water, Glycerin, Aloe Barbadensis Leaf Juice, Polysorbate 20, Olea Europaea (Olive) Fruit Oil, Urtica Dioica (Nettle) Extract, Anthemis Nobilis Flower Extract, Symphytum Officinale Leaf Extract, Calendula Officinalis Flower Extract, Salvia Officinalis (Sage) Extract, Rosmarinus Officinalis (Rosemary) Leaf Extract, Equisetum Arvense Extract, Mentha Piperita (Peppermint) Leaf Extract, Arctium Lappa Root Extract, Kelp Extract, Honey, Sodium PCA, Sea Salt, Citric Acid, Panthenol, Potassium Sorbate, Sodium Hydroxymethylglycinate, Fragrance. Supercurl Moisture Creme: Water, Glycine Soja (Soybean) Oil, Glycerin, Cocos Nucifera (Coconut) Oil, Honey, Polymide-1, Caprylic/Capric Triglyceride, Butyrospermum Parkii (Shea Butter), Fragrance, Cetearyl Alcohol, Ceteareth-20, Glyceryl Stearate, Olea Europaea (Olive) Fruit Oil, Aloe Barbadensis (Aloe Vera) Leaf Extract, Prunus Amygdalus Dulcis (Sweet Almond) Oil, Macadamia Ternifolia (Macadamia) Seed Oil, Potassium Hydroxide, Xanthan Gum, Carbomer, Tetrasodium EDTA, Phenoxyethanol, Caprylyl Glycol, Potassium Sorbate, Caramel. Extra Butter Curl Foaming Creame: Water, Cocos Nucifera (Coconut) Oil, Glycerin, Elaeis Guineensis (Palm) Kernel Oil, Butyrospermum Parkii (Shea Butter), Glyceryl Stearate, Stearic Acid, Cetearyl Alochol, Organic Aloe Barbadensis (Aloe Vera) Leaf Extract, Caprylic/Capric Tryglyceride, Prunus Amygdalus Dulcis (Sweet Almond) Oil, Macadamia Ternifolia (Macadamia) Seed Oil, Fragrance, Potassium Hydroxide, Xanthan Gum, Carbomer, Phenoxyethanol, Caprylyl Glycol, Potassium Sorbate, Tetrasodium EDTA. Curly Magic: Water, Glycerin, Aloe Barbadensis (Aloe Vera) Leaf Juice*, Simmendsia Chinensis (Jojoba) Seed Oil, Hydrolyzed Wheat Protein, Althaea Officinalis (Marshmallow) Root Extract, Urtica Dioica (Nettle) Extract, Equisetum Arvense (Horsetail) Extract, Tocopherol (Vitamin E), Phenoxyethanol, Ethylhexylglycerin, Fragrance *Organically Sourced Thirsty Curls: Water, Polysorbate 20, Glycerin, Cetrimonium Chloride, Polyquatemium-11, PEG-8, Cocos Nucifera (Coconut) Milk, Urtica Dioica (Nettle) Extract, Anthemis Nobilis (Chamomile) Flower Extract, Symphytum Officinale (Comfrey) Leaf Extract, Calendula Officinalis (Marigold) Flower Extract, Salvia Officinalis (Sage) Leaf Extract, Rosmarinus Officinalis (Rosemary) Leaf Extract, Equisetum Arvense (Horsetail) Leaf Extract, Sodium Hyaluronate, Sodium PCA, Panthenol, Magnesium Sulfate, PEG-12 Dimethicone, Citric Acid, Potassium Sorbate, Phenoxyethanol, Caprylyl Glycol, Sodium Hydroxymethylglycinate, Fragrance. | BS12: kg | BU12: 40.37 | BV12: active
A13: =S13 -> DUO-CRSCU-100 | B13: the-doux-crazy-sexy-curl-honey-setting-foam | C13: The Doux Crazy Sexy Curl Honey Setting Foam | D13: <p><span>WHAT IT DOUX? “What about your coils?!?” This ALL IN 1 Styler conditions, detangles, defines and sets wash &amp; go’s…(*catches breath*), twist-outs, braids and TWA’s in one step! Fast-drying with a strong, but flexible hold. No frizz. No flaking. No cap! Just #Science</span></p> <p><span>WHAT’S GOOD?</span></p> <ul> <li> <span>Honey: Fights Frizz. </span><span>Smells good.</span> </li> <li><span>Aloe: Moisturizes + Hydrates hair</span></li> <li><span>Bamboo: Strengthens + Holds</span></li> </ul> | E13: The Doux | F13: Health & Beauty > Personal Care > Hair Care > Hair Styling Products | G13: Styler | H13: Curl Definer, Curl Defining, Curl defining mousse, Curl definition, Curl Styling, Curly Hair, flexible hold, Hair Styling, Kid Safe, Mummy & Me Edit, Natural, Natural Hair, New Arrivals, Protective Styling, Styler, Styling, Styling Foam, Styling Mousse, Sulfate - Free, The Doux, The Doux Crazy Sexy Curl Setting Foam, Twist out, Twists, Wash- n -go | I13: TRUE | J13: Size | K13: 3.4 oz | S13: DUO-CRSCU-100 | T13: 230 | U13: shopify | V13: deny | W13: manual | X13: 45 | Z13: TRUE | AA13: TRUE | AF13: 850031703476 | AG13: https://cdn.shopify.com/s/files/1/0504/5187/3989/files/76A827DB-DDEF-421C-9F3C-C58DEF4C97FF.jpg?v=1748263840 | AH13: 1 | AI13: The Doux Bee Girl Honey Curl Custard | AJ13: FALSE | AL13: The Doux Crazy Sexy Setting Foam: Discover the multi purpose styling foam that fights frizz, detangles, hydrates & defines curls. for twist/braids out, Twa | AM13: 1901 | AY13: The Doux is an award winning brand of super-fresh, texture focused solutions inspired by the life of a stylist and love for the culture. Merging old-school flava with new-school science. The Doux developed a range of simple, multi-functional formulas designed to put an end to the complicated regimens and conflicting information that are shattering your confidence. | AZ13: The Doux | BA13: DOUX YOU: For best results, DO NOT apply oil to the hair before applying this product. <br> We mean it! <br> Apply a juicy amount to clean, damp hair in small sections, smoothing from roots to ends. <br> Air dry, hood dry, or diffuse. <br> Allow hair to dry 100% before separating curls. | BB13: Aqua (Water, Eau), Polyquaternium-55, Cocamidopropyl Hydroxysultaine, Aloe Barbadensis Leaf Juice, Panthenol, Pvp, Hydroxypropyltrimonium Honey, Bambusa Vulgaris (Bamboo) Extract, Propanediol, Disodium Edta, Silk Amino Acids, Tocopheryl Acetate, Polysorbate 20, Ethylhexylglycerin, Oleth-20, Parfum (Fragrance), Glycereth-2 Cocoate, Phenoxyethanol, Sorbic Acid, Caramel, Benzoic Acid, Coumarin | BN13: the-doux-bee-girl-honey-curl-custard | BP13: only manual | BR13: https://cdn.shopify.com/s/files/1/0504/5187/3989/files/09042FD7-14A0-4BA8-BE34-18A75278C142.webp?v=1748263901 | BS13: kg | BU13: 21.98 | BV13: active
